[2025-08-02T12:10:01.318+0000] {taskinstance.py:1956} INFO - Dependencies all met for dep_context=non-requeueable deps ti=<TaskInstance: marine_data_etl_dag.phyto_etl.download_phyto manual__2025-08-02T12:09:23.082188+00:00 [queued]>
[2025-08-02T12:10:01.334+0000] {taskinstance.py:1956} INFO - Dependencies all met for dep_context=requeueable deps ti=<TaskInstance: marine_data_etl_dag.phyto_etl.download_phyto manual__2025-08-02T12:09:23.082188+00:00 [queued]>
[2025-08-02T12:10:01.335+0000] {taskinstance.py:2170} INFO - Starting attempt 1 of 1
[2025-08-02T12:10:01.356+0000] {taskinstance.py:2191} INFO - Executing <Task(PythonOperator): phyto_etl.download_phyto> on 2025-08-02 12:09:23.082188+00:00
[2025-08-02T12:10:01.362+0000] {standard_task_runner.py:60} INFO - Started process 202 to run task
[2025-08-02T12:10:01.369+0000] {standard_task_runner.py:87} INFO - Running: ['***', 'tasks', 'run', 'marine_data_etl_dag', 'phyto_etl.download_phyto', 'manual__2025-08-02T12:09:23.082188+00:00', '--job-id', '18', '--raw', '--subdir', 'DAGS_FOLDER/marine_data_etl_dag.py', '--cfg-path', '/tmp/tmp0jkk87mt']
[2025-08-02T12:10:01.375+0000] {standard_task_runner.py:88} INFO - Job 18: Subtask phyto_etl.download_phyto
[2025-08-02T12:10:01.452+0000] {task_command.py:423} INFO - Running <TaskInstance: marine_data_etl_dag.phyto_etl.download_phyto manual__2025-08-02T12:09:23.082188+00:00 [running]> on host 2376c0e44f50
[2025-08-02T12:10:01.766+0000] {taskinstance.py:2480} INFO - Exporting env vars: AIRFLOW_CTX_DAG_OWNER='***' AIRFLOW_CTX_DAG_ID='marine_data_etl_dag' AIRFLOW_CTX_TASK_ID='phyto_etl.download_phyto' AIRFLOW_CTX_EXECUTION_DATE='2025-08-02T12:09:23.082188+00:00' AIRFLOW_CTX_TRY_NUMBER='1' AIRFLOW_CTX_DAG_RUN_ID='manual__2025-08-02T12:09:23.082188+00:00'
[2025-08-02T12:10:01.770+0000] {taskinstance.py:2698} ERROR - Task failed with exception
Traceback (most recent call last):
  File "/home/airflow/.local/lib/python3.10/site-packages/airflow/models/taskinstance.py", line 433, in _execute_task
    result = execute_callable(context=context, **execute_callable_kwargs)
  File "/home/airflow/.local/lib/python3.10/site-packages/airflow/operators/python.py", line 199, in execute
    return_value = self.execute_callable()
  File "/home/airflow/.local/lib/python3.10/site-packages/airflow/operators/python.py", line 216, in execute_callable
    return self.python_callable(*self.op_args, **self.op_kwargs)
  File "/opt/airflow/dags/etl/download_phytoplankton.py", line 7, in download_phytoplankton
    os.makedirs(output_dir, exist_ok=True)
  File "/usr/local/lib/python3.10/os.py", line 225, in makedirs
    mkdir(name, mode)
FileNotFoundError: [Errno 2] No such file or directory: '/opt/airflow/csv/phytoplankton'
[2025-08-02T12:10:01.792+0000] {taskinstance.py:1138} INFO - Marking task as FAILED. dag_id=marine_data_etl_dag, task_id=phyto_etl.download_phyto, execution_date=20250802T120923, start_date=20250802T121001, end_date=20250802T121001
[2025-08-02T12:10:01.808+0000] {standard_task_runner.py:107} ERROR - Failed to execute job 18 for task phyto_etl.download_phyto ([Errno 2] No such file or directory: '/opt/airflow/csv/phytoplankton'; 202)
[2025-08-02T12:10:01.822+0000] {local_task_job_runner.py:234} INFO - Task exited with return code 1
[2025-08-02T12:10:01.860+0000] {taskinstance.py:3280} INFO - 0 downstream tasks scheduled from follow-on schedule check
