[2025-08-03T07:08:44.779+0000] {taskinstance.py:1956} INFO - Dependencies all met for dep_context=non-requeueable deps ti=<TaskInstance: marine_data_etl_dag.zooplankton_etl.load_zoo manual__2025-08-03T06:41:01+00:00 [queued]>
[2025-08-03T07:08:44.796+0000] {taskinstance.py:1956} INFO - Dependencies all met for dep_context=requeueable deps ti=<TaskInstance: marine_data_etl_dag.zooplankton_etl.load_zoo manual__2025-08-03T06:41:01+00:00 [queued]>
[2025-08-03T07:08:44.797+0000] {taskinstance.py:2170} INFO - Starting attempt 1 of 1
[2025-08-03T07:08:44.820+0000] {taskinstance.py:2191} INFO - Executing <Task(PythonOperator): zooplankton_etl.load_zoo> on 2025-08-03 06:41:01+00:00
[2025-08-03T07:08:44.828+0000] {standard_task_runner.py:60} INFO - Started process 484 to run task
[2025-08-03T07:08:44.835+0000] {standard_task_runner.py:87} INFO - Running: ['***', 'tasks', 'run', 'marine_data_etl_dag', 'zooplankton_etl.load_zoo', 'manual__2025-08-03T06:41:01+00:00', '--job-id', '251', '--raw', '--subdir', 'DAGS_FOLDER/marine_data_etl_dag.py', '--cfg-path', '/tmp/tmpjy1913u7']
[2025-08-03T07:08:44.841+0000] {standard_task_runner.py:88} INFO - Job 251: Subtask zooplankton_etl.load_zoo
[2025-08-03T07:08:44.921+0000] {task_command.py:423} INFO - Running <TaskInstance: marine_data_etl_dag.zooplankton_etl.load_zoo manual__2025-08-03T06:41:01+00:00 [running]> on host e2f3b0101b9e
[2025-08-03T07:08:45.636+0000] {taskinstance.py:2480} INFO - Exporting env vars: AIRFLOW_CTX_DAG_OWNER='***' AIRFLOW_CTX_DAG_ID='marine_data_etl_dag' AIRFLOW_CTX_TASK_ID='zooplankton_etl.load_zoo' AIRFLOW_CTX_EXECUTION_DATE='2025-08-03T06:41:01+00:00' AIRFLOW_CTX_TRY_NUMBER='1' AIRFLOW_CTX_DAG_RUN_ID='manual__2025-08-03T06:41:01+00:00'
[2025-08-03T07:08:45.992+0000] {logging_mixin.py:188} INFO - âœ… Loaded zooplankton to DuckDB: chanthaburi_1_zooplankton
[2025-08-03T07:08:45.998+0000] {taskinstance.py:2698} ERROR - Task failed with exception
Traceback (most recent call last):
  File "/home/airflow/.local/lib/python3.10/site-packages/airflow/models/taskinstance.py", line 433, in _execute_task
    result = execute_callable(context=context, **execute_callable_kwargs)
  File "/home/airflow/.local/lib/python3.10/site-packages/airflow/operators/python.py", line 199, in execute
    return_value = self.execute_callable()
  File "/home/airflow/.local/lib/python3.10/site-packages/airflow/operators/python.py", line 216, in execute_callable
    return self.python_callable(*self.op_args, **self.op_kwargs)
  File "/opt/airflow/dags/etl/load_zooplankton_to_duckdb.py", line 14, in load_zooplankton_csv_to_duckdb
    con.execute(f"CREATE OR REPLACE TABLE {table_name} AS SELECT * FROM read_csv_auto('{path}');")
duckdb.duckdb.ParserException: Parser Error: syntax error at or near "1"
[2025-08-03T07:08:46.020+0000] {taskinstance.py:1138} INFO - Marking task as FAILED. dag_id=marine_data_etl_dag, task_id=zooplankton_etl.load_zoo, execution_date=20250803T064101, start_date=20250803T070844, end_date=20250803T070846
[2025-08-03T07:08:46.038+0000] {standard_task_runner.py:107} ERROR - Failed to execute job 251 for task zooplankton_etl.load_zoo (Parser Error: syntax error at or near "1"; 484)
[2025-08-03T07:08:46.077+0000] {local_task_job_runner.py:234} INFO - Task exited with return code 1
[2025-08-03T07:08:46.117+0000] {taskinstance.py:3280} INFO - 0 downstream tasks scheduled from follow-on schedule check
