[2025-08-02T12:04:21.215+0000] {taskinstance.py:1956} INFO - Dependencies all met for dep_context=non-requeueable deps ti=<TaskInstance: marine_data_etl_dag.zooplankton_etl.download_zoo manual__2025-08-02T12:03:26.415513+00:00 [queued]>
[2025-08-02T12:04:21.232+0000] {taskinstance.py:1956} INFO - Dependencies all met for dep_context=requeueable deps ti=<TaskInstance: marine_data_etl_dag.zooplankton_etl.download_zoo manual__2025-08-02T12:03:26.415513+00:00 [queued]>
[2025-08-02T12:04:21.233+0000] {taskinstance.py:2170} INFO - Starting attempt 1 of 1
[2025-08-02T12:04:21.256+0000] {taskinstance.py:2191} INFO - Executing <Task(PythonOperator): zooplankton_etl.download_zoo> on 2025-08-02 12:03:26.415513+00:00
[2025-08-02T12:04:21.264+0000] {standard_task_runner.py:60} INFO - Started process 152 to run task
[2025-08-02T12:04:21.271+0000] {standard_task_runner.py:87} INFO - Running: ['***', 'tasks', 'run', 'marine_data_etl_dag', 'zooplankton_etl.download_zoo', 'manual__2025-08-02T12:03:26.415513+00:00', '--job-id', '13', '--raw', '--subdir', 'DAGS_FOLDER/marine_data_etl_dag.py', '--cfg-path', '/tmp/tmp7slnh6ai']
[2025-08-02T12:04:21.279+0000] {standard_task_runner.py:88} INFO - Job 13: Subtask zooplankton_etl.download_zoo
[2025-08-02T12:04:21.359+0000] {task_command.py:423} INFO - Running <TaskInstance: marine_data_etl_dag.zooplankton_etl.download_zoo manual__2025-08-02T12:03:26.415513+00:00 [running]> on host 2376c0e44f50
[2025-08-02T12:04:21.714+0000] {taskinstance.py:2480} INFO - Exporting env vars: AIRFLOW_CTX_DAG_OWNER='***' AIRFLOW_CTX_DAG_ID='marine_data_etl_dag' AIRFLOW_CTX_TASK_ID='zooplankton_etl.download_zoo' AIRFLOW_CTX_EXECUTION_DATE='2025-08-02T12:03:26.415513+00:00' AIRFLOW_CTX_TRY_NUMBER='1' AIRFLOW_CTX_DAG_RUN_ID='manual__2025-08-02T12:03:26.415513+00:00'
[2025-08-02T12:04:21.718+0000] {taskinstance.py:2698} ERROR - Task failed with exception
Traceback (most recent call last):
  File "/home/airflow/.local/lib/python3.10/site-packages/airflow/models/taskinstance.py", line 433, in _execute_task
    result = execute_callable(context=context, **execute_callable_kwargs)
  File "/home/airflow/.local/lib/python3.10/site-packages/airflow/operators/python.py", line 199, in execute
    return_value = self.execute_callable()
  File "/home/airflow/.local/lib/python3.10/site-packages/airflow/operators/python.py", line 216, in execute_callable
    return self.python_callable(*self.op_args, **self.op_kwargs)
  File "/opt/airflow/dags/etl/download_zooplankton.py", line 7, in download_zooplankton
    os.makedirs(output_dir, exist_ok=True)
  File "/usr/local/lib/python3.10/os.py", line 225, in makedirs
    mkdir(name, mode)
FileNotFoundError: [Errno 2] No such file or directory: '/opt/airflow/csv/zooplankton'
[2025-08-02T12:04:21.737+0000] {taskinstance.py:1138} INFO - Marking task as FAILED. dag_id=marine_data_etl_dag, task_id=zooplankton_etl.download_zoo, execution_date=20250802T120326, start_date=20250802T120421, end_date=20250802T120421
[2025-08-02T12:04:21.753+0000] {standard_task_runner.py:107} ERROR - Failed to execute job 13 for task zooplankton_etl.download_zoo ([Errno 2] No such file or directory: '/opt/airflow/csv/zooplankton'; 152)
[2025-08-02T12:04:21.805+0000] {local_task_job_runner.py:234} INFO - Task exited with return code 1
[2025-08-02T12:04:21.846+0000] {taskinstance.py:3280} INFO - 0 downstream tasks scheduled from follow-on schedule check
