[2025-08-02T12:03:53.651+0000] {taskinstance.py:1956} INFO - Dependencies all met for dep_context=non-requeueable deps ti=<TaskInstance: marine_data_etl_dag.so_etl.download_so manual__2025-08-02T12:03:26.415513+00:00 [queued]>
[2025-08-02T12:03:53.664+0000] {taskinstance.py:1956} INFO - Dependencies all met for dep_context=requeueable deps ti=<TaskInstance: marine_data_etl_dag.so_etl.download_so manual__2025-08-02T12:03:26.415513+00:00 [queued]>
[2025-08-02T12:03:53.665+0000] {taskinstance.py:2170} INFO - Starting attempt 1 of 1
[2025-08-02T12:03:53.686+0000] {taskinstance.py:2191} INFO - Executing <Task(PythonOperator): so_etl.download_so> on 2025-08-02 12:03:26.415513+00:00
[2025-08-02T12:03:53.692+0000] {standard_task_runner.py:60} INFO - Started process 132 to run task
[2025-08-02T12:03:53.699+0000] {standard_task_runner.py:87} INFO - Running: ['***', 'tasks', 'run', 'marine_data_etl_dag', 'so_etl.download_so', 'manual__2025-08-02T12:03:26.415513+00:00', '--job-id', '10', '--raw', '--subdir', 'DAGS_FOLDER/marine_data_etl_dag.py', '--cfg-path', '/tmp/tmpy1riico8']
[2025-08-02T12:03:53.705+0000] {standard_task_runner.py:88} INFO - Job 10: Subtask so_etl.download_so
[2025-08-02T12:03:53.780+0000] {task_command.py:423} INFO - Running <TaskInstance: marine_data_etl_dag.so_etl.download_so manual__2025-08-02T12:03:26.415513+00:00 [running]> on host 2376c0e44f50
[2025-08-02T12:03:54.090+0000] {taskinstance.py:2480} INFO - Exporting env vars: AIRFLOW_CTX_DAG_OWNER='***' AIRFLOW_CTX_DAG_ID='marine_data_etl_dag' AIRFLOW_CTX_TASK_ID='so_etl.download_so' AIRFLOW_CTX_EXECUTION_DATE='2025-08-02T12:03:26.415513+00:00' AIRFLOW_CTX_TRY_NUMBER='1' AIRFLOW_CTX_DAG_RUN_ID='manual__2025-08-02T12:03:26.415513+00:00'
[2025-08-02T12:03:54.096+0000] {taskinstance.py:2698} ERROR - Task failed with exception
Traceback (most recent call last):
  File "/home/airflow/.local/lib/python3.10/site-packages/airflow/models/taskinstance.py", line 433, in _execute_task
    result = execute_callable(context=context, **execute_callable_kwargs)
  File "/home/airflow/.local/lib/python3.10/site-packages/airflow/operators/python.py", line 199, in execute
    return_value = self.execute_callable()
  File "/home/airflow/.local/lib/python3.10/site-packages/airflow/operators/python.py", line 216, in execute_callable
    return self.python_callable(*self.op_args, **self.op_kwargs)
  File "/opt/airflow/dags/etl/download_so.py", line 7, in download_so
    os.makedirs(output_dir, exist_ok=True)
  File "/usr/local/lib/python3.10/os.py", line 225, in makedirs
    mkdir(name, mode)
FileNotFoundError: [Errno 2] No such file or directory: '/opt/airflow/csv/so'
[2025-08-02T12:03:54.116+0000] {taskinstance.py:1138} INFO - Marking task as FAILED. dag_id=marine_data_etl_dag, task_id=so_etl.download_so, execution_date=20250802T120326, start_date=20250802T120353, end_date=20250802T120354
[2025-08-02T12:03:54.133+0000] {standard_task_runner.py:107} ERROR - Failed to execute job 10 for task so_etl.download_so ([Errno 2] No such file or directory: '/opt/airflow/csv/so'; 132)
[2025-08-02T12:03:54.153+0000] {local_task_job_runner.py:234} INFO - Task exited with return code 1
[2025-08-02T12:03:54.269+0000] {taskinstance.py:3280} INFO - 0 downstream tasks scheduled from follow-on schedule check
